/* Ordering of catch block plays an
   important role when exceptions of
   both Base and Derived types are
   involved in the same program. In
   the given example the Base type
   catch block will be executed for
   the Derived type exception thrown. */

#include<iostream>
using namespace std;

class Base
{};
class Derived:public Base
{};

int main()
{
   Base b;
   Derived d;
   try
   {
      cout<<"Inside try"<<endl;
	  throw d;
   }
     catch(Base tempb)
   {
      cout<<"Caught a base"<<endl;
   }
   catch(Derived tempd)
   {
      cout<<"Caught a derived"<<endl;
   }


   cout<<"End"<<endl;

   return 0;
}
